<sdf version='1.9'>
  <model name='hippocampus'>
    <joint name='attachment' type='fixed'>
      <pose relative_to='__model__'>0 0 0 0 0 0</pose>
      <parent>world</parent>
      <child>end_effector_base_link</child>
    </joint>
    <link name='end_effector_base_link'>
      <pose relative_to='attachment'>0 0 0 0 0 0</pose>
      <inertial>
        <pose>0 0 0 0 0 0</pose>
        <mass>0.10000000000000001</mass>
        <inertia>
          <ixx>1.0000000000000001e-05</ixx>
          <ixy>0</ixy>
          <ixz>0</ixz>
          <iyy>1.0000000000000001e-05</iyy>
          <iyz>0</iyz>
          <izz>1.0000000000000001e-05</izz>
        </inertia>
      </inertial>
      <visual name='end_effector_base_link_visual'>
        <pose>0 0 0 0 1.570796326794897 0</pose>
        <geometry>
          <mesh>
            <scale>1 1 1</scale>
            <uri>file:///home/ros-user/uuv/ros2/install/hippo_sim/share/hippo_sim/models/gripper/meshes/base.stl</uri>
          </mesh>
        </geometry>
        <material>
          <ambient>1 1 1 1</ambient>
          <diffuse>1 1 1 1</diffuse>
          <specular>1 1 1 1</specular>
          <pbr>
            <metal>
              <metalness>1</metalness>
              <roughness>0.5</roughness>
              <environment_map>/home/ros-user/uuv/ros2/install/hippo_sim/share/hippo_sim/models/common/textures/env_map.dds</environment_map>
              <albedo_map>/home/ros-user/uuv/ros2/install/hippo_sim/share/hippo_sim/models/common/textures/blue.png</albedo_map>
            </metal>
          </pbr>
        </material>
      </visual>
    </link>
    <joint name='end_effector_prismatic_joint' type='prismatic'>
      <pose relative_to='end_effector_base_link'>0.0069 0 0 0 0 0</pose>
      <parent>end_effector_base_link</parent>
      <child>end_effector_prismatic_link</child>
      <axis>
        <xyz>1 0 0</xyz>
        <limit>
          <lower>0</lower>
          <upper>0.012</upper>
          <effort>28.992000000000001</effort>
          <velocity>2</velocity>
        </limit>
        <dynamics>
          <spring_reference>0</spring_reference>
          <spring_stiffness>0</spring_stiffness>
        </dynamics>
      </axis>
    </joint>
    <link name='end_effector_prismatic_link'>
      <pose relative_to='end_effector_prismatic_joint'>0 0 0 0 0 0</pose>
      <inertial>
        <pose>0 0 0 0 0 0</pose>
        <mass>0.10000000000000001</mass>
        <inertia>
          <ixx>1.0000000000000001e-05</ixx>
          <ixy>0</ixy>
          <ixz>0</ixz>
          <iyy>1.0000000000000001e-05</iyy>
          <iyz>0</iyz>
          <izz>1.0000000000000001e-05</izz>
        </inertia>
      </inertial>
      <visual name='end_effector_prismatic_link_visual'>
        <pose>0 0 0 0 0 0</pose>
        <geometry>
          <cylinder>
            <length>0.02</length>
            <radius>0.0025000000000000001</radius>
          </cylinder>
        </geometry>
      </visual>
    </link>
    <joint name='end_effector_left_inner_revolute_joint' type='revolute'>
      <pose relative_to='end_effector_prismatic_link'>0 0 0 0 0 0</pose>
      <parent>end_effector_prismatic_link</parent>
      <child>end_effector_left_inner_revolute_link</child>
      <axis>
        <xyz>0 0 1</xyz>
        <limit>
          <lower>-10000000000000000</lower>
          <upper>10000000000000000</upper>
        </limit>
        <dynamics>
          <damping>0.59999999999999998</damping>
          <friction>0</friction>
          <spring_reference>0</spring_reference>
          <spring_stiffness>0</spring_stiffness>
        </dynamics>
      </axis>
    </joint>
    <link name='end_effector_left_inner_revolute_link'>
      <pose relative_to='end_effector_left_inner_revolute_joint'>0 0 0 0 0 0</pose>
      <inertial>
        <pose>0 0 0 0 0 0</pose>
        <mass>0.10000000000000001</mass>
        <inertia>
          <ixx>1.0000000000000001e-05</ixx>
          <ixy>0</ixy>
          <ixz>0</ixz>
          <iyy>1.0000000000000001e-05</iyy>
          <iyz>0</iyz>
          <izz>1.0000000000000001e-05</izz>
        </inertia>
      </inertial>
      <visual name='end_effector_left_inner_revolute_link_visual'>
        <pose>0 0 0 0 0 0</pose>
        <geometry>
          <cylinder>
            <length>0.0050000000000000001</length>
            <radius>0.01</radius>
          </cylinder>
        </geometry>
      </visual>
    </link>
    <joint name='end_effector_left_prismatic_joint' type='prismatic'>
      <pose relative_to='end_effector_left_inner_revolute_link'>0 0.007 0 0 0 0</pose>
      <parent>end_effector_left_inner_revolute_link</parent>
      <child>end_effector_left_prismatic_link</child>
      <axis>
        <xyz>0 1 0</xyz>
        <limit>
          <lower>-1</lower>
          <upper>1</upper>
          <effort>100</effort>
          <velocity>1</velocity>
        </limit>
        <dynamics>
          <spring_reference>0</spring_reference>
          <spring_stiffness>0</spring_stiffness>
        </dynamics>
      </axis>
    </joint>
    <link name='end_effector_left_prismatic_link'>
      <pose relative_to='end_effector_left_prismatic_joint'>0 0 0 0 0 0</pose>
      <inertial>
        <pose>0 0 0 0 0 0</pose>
        <mass>0.10000000000000001</mass>
        <inertia>
          <ixx>1.0000000000000001e-05</ixx>
          <ixy>0</ixy>
          <ixz>0</ixz>
          <iyy>1.0000000000000001e-05</iyy>
          <iyz>0</iyz>
          <izz>1.0000000000000001e-05</izz>
        </inertia>
      </inertial>
    </link>
    <joint name='end_effector_left_jaw_joint' type='fixed'>
      <pose relative_to='end_effector_left_prismatic_link'>0 0.008500000000000001 0 0 0 0</pose>
      <parent>end_effector_left_prismatic_link</parent>
      <child>end_effector_left_jaw_link</child>
      <axis>
        <dynamics>
          <spring_reference>0</spring_reference>
          <spring_stiffness>0</spring_stiffness>
        </dynamics>
        <xyz>0 0 1</xyz>
        <limit>
          <lower>-10000000000000000</lower>
          <upper>10000000000000000</upper>
        </limit>
      </axis>
      <physics>
        <ode>
          <limit>
            <cfm>0</cfm>
            <erp>0.20000000000000001</erp>
          </limit>
        </ode>
      </physics>
    </joint>
    <link name='end_effector_left_jaw_link'>
      <pose relative_to='end_effector_left_jaw_joint'>0 0 0 0 0 0</pose>
      <inertial>
        <pose>0 0 0 0 0 0</pose>
        <mass>0.10000000000000001</mass>
        <inertia>
          <ixx>1.0000000000000001e-05</ixx>
          <ixy>0</ixy>
          <ixz>0</ixz>
          <iyy>1.0000000000000001e-05</iyy>
          <iyz>0</iyz>
          <izz>1.0000000000000001e-05</izz>
        </inertia>
      </inertial>
      <visual name='end_effector_left_jaw_link_visual'>
        <pose>0 0 0 0 0 0</pose>
        <geometry>
          <mesh>
            <scale>1 1 1</scale>
            <uri>file:///home/ros-user/uuv/ros2/install/hippo_sim/share/hippo_sim/models/gripper/meshes/left_jaw.stl</uri>
          </mesh>
        </geometry>
      </visual>
    </link>
    <joint name='end_effector_left_revolute_joint' type='revolute'>
      <pose relative_to='end_effector_left_jaw_link'>0 0 0 0 0 0</pose>
      <parent>end_effector_left_jaw_link</parent>
      <child>end_effector_left_revolute_link</child>
      <axis>
        <xyz>0 0 1</xyz>
        <limit>
          <lower>-10000000000000000</lower>
          <upper>10000000000000000</upper>
        </limit>
        <dynamics>
          <damping>0.59999999999999998</damping>
          <friction>0</friction>
          <spring_reference>0</spring_reference>
          <spring_stiffness>0</spring_stiffness>
        </dynamics>
      </axis>
    </joint>
    <link name='end_effector_left_revolute_link'>
      <pose relative_to='end_effector_left_revolute_joint'>0 0 0 0 0 0</pose>
      <inertial>
        <pose>0 0 0 0 0 0</pose>
        <mass>0.10000000000000001</mass>
        <inertia>
          <ixx>1.0000000000000001e-05</ixx>
          <ixy>0</ixy>
          <ixz>0</ixz>
          <iyy>1.0000000000000001e-05</iyy>
          <iyz>0</iyz>
          <izz>1.0000000000000001e-05</izz>
        </inertia>
      </inertial>
      <visual name='end_effector_left_revolute_link_visual'>
        <pose>0 0 0 0 0 0</pose>
        <geometry>
          <cylinder>
            <length>0.02</length>
            <radius>0.0025000000000000001</radius>
          </cylinder>
        </geometry>
      </visual>
    </link>
    <joint name='end_effector_right_inner_revolute_joint' type='revolute'>
      <pose relative_to='end_effector_prismatic_link'>0 0 0 0 0 0</pose>
      <parent>end_effector_prismatic_link</parent>
      <child>end_effector_right_inner_revolute_link</child>
      <axis>
        <xyz>0 0 1</xyz>
        <limit>
          <lower>-10000000000000000</lower>
          <upper>10000000000000000</upper>
        </limit>
        <dynamics>
          <damping>0.59999999999999998</damping>
          <friction>0</friction>
          <spring_reference>0</spring_reference>
          <spring_stiffness>0</spring_stiffness>
        </dynamics>
      </axis>
    </joint>
    <link name='end_effector_right_inner_revolute_link'>
      <pose relative_to='end_effector_right_inner_revolute_joint'>0 0 0 0 0 0</pose>
      <inertial>
        <pose>0 0 0 0 0 0</pose>
        <mass>0.10000000000000001</mass>
        <inertia>
          <ixx>1.0000000000000001e-05</ixx>
          <ixy>0</ixy>
          <ixz>0</ixz>
          <iyy>1.0000000000000001e-05</iyy>
          <iyz>0</iyz>
          <izz>1.0000000000000001e-05</izz>
        </inertia>
      </inertial>
      <visual name='end_effector_right_inner_revolute_link_visual'>
        <pose>0 0 0 0 0 0</pose>
        <geometry>
          <cylinder>
            <length>0.0050000000000000001</length>
            <radius>0.01</radius>
          </cylinder>
        </geometry>
      </visual>
    </link>
    <joint name='end_effector_right_prismatic_joint' type='prismatic'>
      <pose relative_to='end_effector_right_inner_revolute_link'>0 -0.007 0 0 0 0</pose>
      <parent>end_effector_right_inner_revolute_link</parent>
      <child>end_effector_right_prismatic_link</child>
      <axis>
        <xyz>0 1 0</xyz>
        <limit>
          <lower>-1</lower>
          <upper>1</upper>
          <effort>100</effort>
          <velocity>1</velocity>
        </limit>
        <dynamics>
          <spring_reference>0</spring_reference>
          <spring_stiffness>0</spring_stiffness>
        </dynamics>
      </axis>
    </joint>
    <link name='end_effector_right_prismatic_link'>
      <pose relative_to='end_effector_right_prismatic_joint'>0 0 0 0 0 0</pose>
      <inertial>
        <pose>0 0 0 0 0 0</pose>
        <mass>0.10000000000000001</mass>
        <inertia>
          <ixx>1.0000000000000001e-05</ixx>
          <ixy>0</ixy>
          <ixz>0</ixz>
          <iyy>1.0000000000000001e-05</iyy>
          <iyz>0</iyz>
          <izz>1.0000000000000001e-05</izz>
        </inertia>
      </inertial>
    </link>
    <joint name='end_effector_right_jaw_joint' type='fixed'>
      <pose relative_to='end_effector_right_prismatic_link'>0 -0.008500000000000001 0 0 0 0</pose>
      <parent>end_effector_right_prismatic_link</parent>
      <child>end_effector_right_jaw_link</child>
      <axis>
        <dynamics>
          <spring_reference>0</spring_reference>
          <spring_stiffness>0</spring_stiffness>
        </dynamics>
        <xyz>0 0 1</xyz>
        <limit>
          <lower>-10000000000000000</lower>
          <upper>10000000000000000</upper>
        </limit>
      </axis>
      <physics>
        <ode>
          <limit>
            <cfm>0</cfm>
            <erp>0.20000000000000001</erp>
          </limit>
        </ode>
      </physics>
    </joint>
    <link name='end_effector_right_jaw_link'>
      <pose relative_to='end_effector_right_jaw_joint'>0 0 0 0 0 0</pose>
      <inertial>
        <pose>0 0 0 0 0 0</pose>
        <mass>0.10000000000000001</mass>
        <inertia>
          <ixx>1.0000000000000001e-05</ixx>
          <ixy>0</ixy>
          <ixz>0</ixz>
          <iyy>1.0000000000000001e-05</iyy>
          <iyz>0</iyz>
          <izz>1.0000000000000001e-05</izz>
        </inertia>
      </inertial>
      <visual name='end_effector_right_jaw_link_visual'>
        <pose>0 0 0 0 0 0</pose>
        <geometry>
          <mesh>
            <scale>1 1 1</scale>
            <uri>file:///home/ros-user/uuv/ros2/install/hippo_sim/share/hippo_sim/models/gripper/meshes/right_jaw.stl</uri>
          </mesh>
        </geometry>
      </visual>
    </link>
    <joint name='end_effector_right_revolute_joint' type='revolute'>
      <pose relative_to='end_effector_right_jaw_link'>0 0 0 0 0 0</pose>
      <parent>end_effector_right_jaw_link</parent>
      <child>end_effector_right_revolute_link</child>
      <axis>
        <xyz>0 0 1</xyz>
        <limit>
          <lower>-10000000000000000</lower>
          <upper>10000000000000000</upper>
        </limit>
        <dynamics>
          <damping>0.59999999999999998</damping>
          <friction>0</friction>
          <spring_reference>0</spring_reference>
          <spring_stiffness>0</spring_stiffness>
        </dynamics>
      </axis>
    </joint>
    <link name='end_effector_right_revolute_link'>
      <pose relative_to='end_effector_right_revolute_joint'>0 0 0 0 0 0</pose>
      <inertial>
        <pose>0 0 0 0 0 0</pose>
        <mass>0.10000000000000001</mass>
        <inertia>
          <ixx>1.0000000000000001e-05</ixx>
          <ixy>0</ixy>
          <ixz>0</ixz>
          <iyy>1.0000000000000001e-05</iyy>
          <iyz>0</iyz>
          <izz>1.0000000000000001e-05</izz>
        </inertia>
      </inertial>
      <visual name='end_effector_right_revolute_link_visual'>
        <pose>0 0 0 0 0 0</pose>
        <geometry>
          <cylinder>
            <length>0.02</length>
            <radius>0.0025000000000000001</radius>
          </cylinder>
        </geometry>
      </visual>
    </link>
    <plugin name='gz::sim::systems::DetachableJoint' filename='libgz-sim-detachable-joint-system.so'>
      <parent_link>end_effector_left_revolute_link</parent_link>
      <child_model>hippocampus</child_model>
      <child_link>end_effector_base_link</child_link>
    </plugin>
    <plugin name='gz::sim::systems::DetachableJoint' filename='libgz-sim-detachable-joint-system.so'>
      <parent_link>end_effector_right_revolute_link</parent_link>
      <child_model>hippocampus</child_model>
      <child_link>end_effector_base_link</child_link>
    </plugin>
    <plugin name='ignition::gazebo::systems::JointStatePublisher' filename='libignition-gazebo-joint-state-publisher-system.so'/>
    <plugin name='ignition::gazebo::systems::ApplyJointForce' filename='libignition-gazebo-apply-joint-force-system.so'>
      <joint_name>end_effector_prismatic_joint</joint_name>
    </plugin>
  </model>
</sdf>
