<?xml version="1.0" ?>
<!-- =================================================================================== -->
<!-- |    This document was autogenerated by xacro from gripper.xacro                  | -->
<!-- |    EDITING THIS FILE BY HAND IS NOT RECOMMENDED                                 | -->
<!-- =================================================================================== -->
<robot name="hippocampus">
  <link name="world"/>
  <joint name="attachment" type="fixed">
    <parent link="world"/>
    <child link="base_link"/>
  </joint>
  <link name="base_link">
    <inertial>
      <mass value="0.1"/>
      <inertia ixx="1e-5" ixy="0.0" ixz="0.0" iyy="1e-5" iyz="0.0" izz="1e-5"/>
    </inertial>
    <visual>
      <geometry>
        <sphere radius="0.05"/>
      </geometry>
    </visual>
  </link>
  <!--
    <joint name="left_fixed_joint" type="fixed">
        <parent link="base_link" />
        <origin xyz="1 1 0" rpy="0 0 0" />
        <child link="left_rotation_link" />
    </joint>
    -->
  <link name="prismatic_link">
    <inertial>
      <mass value="0.1"/>
      <inertia ixx="1e-5" ixy="0.0" ixz="0.0" iyy="1e-5" iyz="0.0" izz="1e-5"/>
    </inertial>
    <visual>
      <origin rpy="0 1.57 0" xyz="0 0 0"/>
      <geometry>
        <cylinder length="0.1" radius="0.05"/>
      </geometry>
    </visual>
  </link>
  <joint name="prismatic_joint" type="prismatic">
    <parent link="base_link"/>
    <child link="prismatic_link"/>
    <axis xyz="1 0 0"/>
    <limit effort="100" lower="-1.0" upper=" 1.0" velocity="1.0"/>
    <origin xyz="1 0 0"/>
  </joint>
  <link name="left_prismatic_revolute_link">
    <inertial>
      <mass value="0.1"/>
      <inertia ixx="1e-5" ixy="0.0" ixz="0.0" iyy="1e-5" iyz="0.0" izz="1e-5"/>
    </inertial>
    <visual>
      <origin rpy="1.57 0 0" xyz="0 0.5 0"/>
      <geometry>
        <cylinder length="0.3" radius="0.02"/>
      </geometry>
    </visual>
  </link>
  <joint name="left_prismatic_revolute_joint" type="continuous">
    <parent link="prismatic_link"/>
    <child link="left_prismatic_revolute_link"/>
    <axis xyz="0 0 1"/>
    <dynamics damping="1.0" friction="0.0"/>
  </joint>
  <link name="left_jaw">
    <inertial>
      <mass value="0.1"/>
      <inertia ixx="1e-5" ixy="0.0" ixz="0.0" iyy="1e-5" iyz="0.0" izz="1e-5"/>
    </inertial>
    <visual>
      <origin rpy="0 1.57 0" xyz="0.4 0 0"/>
      <geometry>
        <cylinder length="0.8" radius="0.01"/>
      </geometry>
    </visual>
  </link>
  <joint name="left_jaw_joint" type="fixed">
    <parent link="left_rotation_dummy_link"/>
    <child link="left_jaw"/>
    <origin xyz="0 0 0"/>
  </joint>
  <link name="left_prismatic_link">
    <inertial>
      <mass value="0.1"/>
      <inertia ixx="1e-5" ixy="0.0" ixz="0.0" iyy="1e-5" iyz="0.0" izz="1e-5"/>
    </inertial>
    <visual>
      <origin rpy="-1.57 0 0" xyz="0 0 0"/>
      <geometry>
        <cylinder length="0.1" radius="0.05"/>
      </geometry>
    </visual>
  </link>
  <joint name="left_prismatic_joint" type="prismatic">
    <parent link="left_prismatic_revolute_link"/>
    <child link="left_prismatic_link"/>
    <axis xyz="0 1 0"/>
    <limit effort="100" lower="-1.0" upper="1.0" velocity="1.0"/>
    <origin xyz="0 0.5 0"/>
  </joint>
  <link name="left_rotation_link">
    <origin xyz="0 0 0"/>
    <inertial>
      <mass value="0.1"/>
      <inertia ixx="1e-5" ixy="0.0" ixz="0.0" iyy="1e-5" iyz="0.0" izz="1e-5"/>
    </inertial>
    <visual>
      <geometry>
        <box size="0.1 0.1 0.1"/>
      </geometry>
    </visual>
  </link>
  <joint name="left_revolute_joint" type="continuous">
    <parent link="left_rotation_dummy_link"/>
    <child link="left_rotation_link"/>
    <axis xyz="0 0 1"/>
    <origin xyz="0 0 0"/>
    <dynamics damping="0.6" friction="0.0"/>
  </joint>
  <link name="left_rotation_dummy_link">
    <origin xyz="0 0 0"/>
    <inertial>
      <mass value="0.1"/>
      <inertia ixx="1e-5" ixy="0.0" ixz="0.0" iyy="1e-5" iyz="0.0" izz="1e-5"/>
    </inertial>
    <visual>
      <geometry>
        <box size="0.01 0.01 0.5"/>
      </geometry>
    </visual>
  </link>
  <joint name="dummy_joint" type="fixed">
    <parent link="left_prismatic_link"/>
    <child link="left_rotation_dummy_link"/>
    <origin xyz="0 0.5 0"/>
    <axis xyz="0 0 1"/>
    <limit effort="10" lower="0.7853981633974483" upper="0.7853981633974483" velocity="1"/>
  </joint>
  <gazebo>
    <disableFixedJointLumping>true</disableFixedJointLumping>
    <plugin filename="libgz-sim-detachable-joint-system.so" name="gz::sim::systems::DetachableJoint">
      <parent_link>left_rotation_link</parent_link>
      <child_model>hippocampus</child_model>
      <child_link>base_link</child_link>
    </plugin>
    <plugin filename="libignition-gazebo-joint-state-publisher-system.so" name="ignition::gazebo::systems::JointStatePublisher"/>
    <plugin filename="libignition-gazebo-apply-joint-force-system.so" name="ignition::gazebo::systems::ApplyJointForce">
      <joint_name>prismatic_joint</joint_name>
    </plugin>
    <plugin filename="libignition-gazebo-apply-joint-force-system.so" name="ignition::gazebo::systems::ApplyJointForce">
      <joint_name>left_prismatic_revolute_joint</joint_name>
    </plugin>
    <plugin filename="libignition-gazebo-apply-joint-force-system.so" name="ignition::gazebo::systems::ApplyJointForce">
      <joint_name>left_revolute_joint</joint_name>
    </plugin>
  </gazebo>
</robot>
